Workbook

Sheet Abstract Approval Checklist
E2: <-- Best botany talk consideration | F2: Raw Abstract Submission Data: | G2: https://brocku-my.sharepoint.com/:x:/r/personal/nb21ts_brocku_ca/Documents/OE3C%202026%20Abstract%20Submission.xlsx?d=w459c53552a944aa08c2aeba44f42c6c0&csf=1&web=1&e=4s9HcS
I3: Reviewers
I4: Nick | K4: Katharine | M4: Cassia | O4: Sarah | Q4: Lauren
A5: Status | B5: Abstract Number (Old) | C5: Abstract Number (New) | D5: Link to Abstract | E5: Name of Submitter | F5: Keywords | G5: Type of presentation | H5: "E" Allignment | I5: Approve? | J5: Comments | K5: Approve?2 | L5: Comments3 | M5: Approve?4 | N5: Comments5 | O5: Approve?10 | P5: Comments11 | Q5: Approve?14 | R5: Comments15
A6: =IF(COUNTIF(I6:R6, TRUE) >= 2, "Complete", "In Progress") -> Complete | B6: 7 | C6: LT5 | D6: Abstract | E6: Elora Nabon | F6: none | G6: Lightning Talk | H6: Ecology | I6: FALSE | K6: FALSE | M6: TRUE | O6: FALSE | Q6: TRUE
A7: =IF(COUNTIF(I7:R7, TRUE) >= 2, "Complete", "In Progress") -> Complete | B7: 19 | C7: LT3 | D7: Abstract | E7: Alexia Kallmes* | F7: connectivity, resilience, network, functional traits | G7: Lightning Talk | H7: Ecology | I7: TRUE | J7: Needs to be a fiull length talk for award. | K7: FALSE | M7: FALSE | O7: TRUE | Q7: FALSE
A8: =IF(COUNTIF(I8:R8, TRUE) >= 2, "Complete", "In Progress") -> Complete | B8: 20 | C8: LT1 | D8: Abstract | E8: Julia Atteck | F8: paleolimnology, cladoceran zooplankton, sulfate deposition, climate change, dissolved organic carbon (DOC) | G8: Lightning Talk | H8: Ecology | I8: TRUE | K8: FALSE | M8: FALSE | O8: TRUE | Q8: FALSE
A9: =IF(COUNTIF(I9:R9, TRUE) >= 2, "Complete", "In Progress") -> Complete | B9: 10 | C9: LT4 | D9: Abstract | E9: Namanpreet Lamba | F9: Mycorrhiza, Heritability, Pleiotropy, Nutrients, Selection | G9: Lightning Talk | H9: Evolution | I9: TRUE | K9: FALSE | M9: FALSE | O9: TRUE | Q9: FALSE
A10: =IF(COUNTIF(I10:Q10,TRUE) >= 2, "Complete", "In Progress") -> In Progress | B10: 1 | C10: P2 | D10: Abstract | E10: Joonsoo Sean Lyeo | F10: Therapeutic landscapes, Urban nature, Health geography, Scoping review | G10: Poster | H10: Ecology | I10: FALSE | K10: FALSE | M10: TRUE | O10: FALSE | Q10: FALSE | R10: Email sent to Nick as this abstract is copy pasted from his published paper which is a no no
A11: =IF(COUNTIF(I11:R11, TRUE) >= 2, "Complete", "In Progress") -> Complete | B11: 3 | C11: P1 | D11: Abstract | E11: Lauren Nesbitt | F11: paleolimnology, holocene, fire, vegetaton, climate reconstruction | G11: Poster | H11: Ecology | I11: FALSE | K11: FALSE | M11: TRUE | O11: TRUE | Q11: FALSE
A12: =IF(COUNTIF(I12:R12, TRUE) >= 2, "Complete", "In Progress") -> Complete | B12: 8 | C12: P13 | D12: Abstract | E12: Kaley Vance | F12: Physiological Colour Change, crypsis, Enrichment, Chinook Salmon, | G12: Poster | H12: Ecology | I12: FALSE | K12: FALSE | M12: TRUE | O12: FALSE | Q12: TRUE
A13: =IF(COUNTIF(I13:R13, TRUE) >= 2, "Complete", "In Progress") -> Complete | B13: 11 | C13: P15 | D13: Abstract | E13: Avery Ng | F13: Benthic Macroinvertebrates, Passive Acoustic Monitoring, Acoustic Complexity Index | G13: Poster | H13: Ecology | I13: FALSE | K13: FALSE | M13: TRUE | O13: FALSE | Q13: TRUE
A14: =IF(COUNTIF(I14:R14, TRUE) >= 2, "Complete", "In Progress") -> Complete | B14: 14 | C14: P10 | D14: Abstract | E14: Johanna Kiik | F14: invasive species, hybridization, phenology, fitness | G14: Poster | H14: Ecology | I14: FALSE | K14: FALSE | M14: FALSE | O14: TRUE | Q14: TRUE
A15: =IF(COUNTIF(I15:R15, TRUE) >= 2, "Complete", "In Progress") -> Complete | B15: 15 | C15: P9 | D15: Abstract | E15: Amanda, Liu | F15: Phenology, fitness, shade competitors, shade avoidance syndrome, spring ephemeral | G15: Poster | H15: Ecology | I15: FALSE | K15: FALSE | M15: FALSE | O15: TRUE | Q15: TRUE
A16: =IF(COUNTIF(I16:R16, TRUE) >= 2, "Complete", "In Progress") -> Complete | B16: 17 | C16: P18 | D16: Abstract | E16: Bethany Duford | F16: birds, sex, ecology, methods, sexual-size dimorphism | G16: Poster | H16: Ecology | I16: TRUE | K16: FALSE | M16: FALSE | O16: TRUE | P16: One author | Q16: FALSE
A17: =IF(COUNTIF(I17:R17, TRUE) >= 2, "Complete", "In Progress") -> Complete | B17: 24 | C17: P8 | D17: Abstract | E17: Noah Rhoden | F17: Ecology, Evolution, Reproduction, Pollination | G17: Poster | H17: Ecology | I17: TRUE | K17: FALSE | M17: FALSE | O17: TRUE | P17: Merged paragraphs- More of a proposal | Q17: FALSE
A18: =IF(COUNTIF(I18:R18, TRUE) >= 2, "Complete", "In Progress") -> Complete | B18: 25 | C18: P4 | D18: Abstract | E18: Harmandeep Singh | F18: Hydroxyl radicals, Clean works, vineyard, lady beetle, pest management | G18: Poster | H18: Ecology | I18: TRUE | K18: FALSE | M18: FALSE | O18: TRUE | P18: One Author, and I added key words as none were listed | Q18: FALSE
A19: =IF(COUNTIF(I19:R19, TRUE) >= 2, "Complete", "In Progress") -> Complete | B19: 28 | C19: P17 | D19: Abstract | E19: Paige, Au | F19: Wildlife, Spatial Ecology, Movement Ecology, Bobcats, Camera-Traps | G19: Poster | H19: Ecology | I19: TRUE | K19: FALSE | M19: FALSE | O19: TRUE | Q19: FALSE
A20: =IF(COUNTIF(I20:R20, TRUE) >= 2, "Complete", "In Progress") -> Complete | B20: 30 | C20: P14 | D20: Abstract | E20: Morgan Mumma | F20: Acid deposition, Cladocera, Reference lakes, Water clarity, DOC | G20: Poster | H20: Ecology | I20: TRUE | K20: FALSE | M20: FALSE | O20: TRUE | P20: Only Author? | Q20: FALSE
A21: =IF(COUNTIF(I21:R21, TRUE) >= 2, "Complete", "In Progress") -> Complete | B21: 31 | C21: P16 | D21: Abstract | E21: Harry, Kumbhani | F21: habitat use, thermoregulation, thermal preference, reptile, ecology | G21: Poster | H21: Ecology | I21: TRUE | J21: Fixed | K21: FALSE | M21: FALSE | O21: TRUE | P21: Tsk tsk Harry, copy and pasted abstract from published paper | Q21: FALSE
A22: =IF(COUNTIF(I22:R22, TRUE) >= 2, "Complete", "In Progress") -> Complete | B22: 34 | C22: P6 | D22: Abstract | E22: Gabriela Santos de Paula | F22: Hypocreales, entomopathogenic, endophytic, whitefly | G22: Poster | H22: Ecology | I22: TRUE | K22: FALSE | M22: FALSE | O22: TRUE | Q22: FALSE
A23: =IF(COUNTIF(I23:R23, TRUE) >= 2, "Complete", "In Progress") -> Complete | B23: 4 | C23: P11 | D23: Abstract | E23: Ella Martin | F23: natural selection, trophic interactions, predation, Eurosta solidaginis, education | G23: Poster | H23: Evolution | I23: FALSE | K23: FALSE | M23: TRUE | O23: FALSE | Q23: TRUE
A24: =IF(COUNTIF(I24:R24, TRUE) >= 2, "Complete", "In Progress") -> Complete | B24: 21 | C24: P3 | D24: Abstract | E24: Linh Nguyen | F24: Redback spiders, Latrodectus hasselti, Urbanization, Urban Heat Island Effect | G24: Poster | H24: Evolution | I24: TRUE | K24: FALSE | M24: FALSE | O24: TRUE | Q24: FALSE
A25: =IF(COUNTIF(I25:R25, TRUE) >= 2, "Complete", "In Progress") -> Complete | B25: 23 | C25: P5 | D25: Abstract | E25: Samia, Saif | F25: Gut development, host-microbe interactions, germ free, morphometrics, cockroach | G25: Poster | H25: Evolution | I25: TRUE | K25: FALSE | M25: FALSE | O25: TRUE | P25: Is the co-author | Q25: FALSE
A26: =IF(COUNTIF(I26:R26, TRUE) >= 2, "Complete", "In Progress") -> Complete | B26: 35 | C26: P19 | D26: Abstract | E26: Anmol Thind | F26: Suicide, Inclusive Fitness, Group dynamics, social bonding | G26: Poster | H26: Evolution | I26: TRUE | K26: FALSE | M26: FALSE | O26: TRUE | P26: One Author, and I added key words as none were listed | Q26: FALSE
A27: =IF(COUNTIF(I27:R27, TRUE) >= 2, "Complete", "In Progress") -> Complete | B27: 38 | C27: P7 | D27: Abstract | E27: Adrija Paul | F27: Speciation, Reproductive Isolation, Caenorhabditis, worms, Evolution | G27: Poster | H27: Evolution | I27: FALSE | K27: TRUE | M27: FALSE | O27: FALSE | Q27: TRUE | R27: italiziations are needed on the scientific name for Drosophila
A28: =IF(COUNTIF(I28:R28, TRUE) >= 2, "Complete", "In Progress") -> Complete | B28: 2 | C28: T4 | D28: Abstract | E28: Sarah Hein | F28: Dendrochronology, climate reconstruction, jack pine, subarctic. | G28: Seminar Talk | H28: Ecology | I28: FALSE | K28: TRUE | M28: TRUE | O28: FALSE | Q28: FALSE
A29: =IF(COUNTIF(I29:R29, TRUE) >= 2, "Complete", "In Progress") -> Complete | B29: 9 | C29: T9 | D29: Abstract | E29: Sarah Dunn | F29: CITY LIVING INVERTEBRATES: EXPLORING ABUNDANCE AND DIVERSITY OF INVERTEBRATES THROUGHOUT IQALUIT, NU | G29: Seminar Talk | H29: Ecology | I29: FALSE | K29: FALSE | M29: TRUE | O29: TRUE | Q29: FALSE
A30: =IF(COUNTIF(I30:R30, TRUE) >= 2, "Complete", "In Progress") -> Complete | B30: 12 | C30: T7 | D30: Abstract | E30: Jennika Mitchell | F30: Greenland halibut, Baffin Bay, Population Assessment Model, Size Distribution, Sex Ratio. | G30: Seminar Talk | H30: Ecology | I30: FALSE | K30: FALSE | M30: FALSE | O30: TRUE | Q30: TRUE
A31: =IF(COUNTIF(I31:R31, TRUE) >= 2, "Complete", "In Progress") -> Complete | B31: 13 | C31: T6 | D31: Abstract | E31: Savannah, Ecclestone | F31: White Shark, Biologging, Tri-axial Accelerometry, Predator Ecology, Foraging Behaviour | G31: Seminar Talk | H31: Ecology | I31: FALSE | K31: FALSE | M31: FALSE | O31: TRUE | Q31: TRUE
A32: =IF(COUNTIF(I32:R32, TRUE) >= 2, "Complete", "In Progress") -> Complete | B32: 18 | C32: T10 | D32: Abstract | E32: Dithara Perera | F32: diatom assemblages, least disturbed lakes | G32: Seminar Talk | H32: Ecology | I32: TRUE | K32: FALSE | M32: FALSE | O32: TRUE | P32: One author | Q32: FALSE
A33: =IF(COUNTIF(I33:R33, TRUE) >= 2, "Complete", "In Progress") -> Complete | B33: 27 | C33: T11 | D33: Abstract | E33: Joe, Armstrong | F33: Bees, Temperature, Environmental Influences, Body Size | G33: Seminar Talk | H33: Ecology | I33: TRUE | K33: FALSE | M33: FALSE | O33: TRUE | P33: One author, and merged paragraphs - this is a proposal | Q33: FALSE
A34: =IF(COUNTIF(I34:R34, TRUE) >= 2, "Complete", "In Progress") -> Complete | B34: 29 | C34: T1 | D34: Abstract | E34: Kayla MacNaughton | F34: Invasive Plants, Land Ethos, Relationality, Ethnobotany | G34: Seminar Talk | H34: Ecology | I34: TRUE | K34: FALSE | M34: FALSE | O34: TRUE | Q34: FALSE
A35: =IF(COUNTIF(I35:R35, TRUE) >= 2, "Complete", "In Progress") -> Complete | B35: 36 | C35: T14 | D35: Abstract | E35: Amber French | F35: Citizen Science, eBird, Observer, Skill, Learning | G35: Seminar Talk | H35: Ecology | I35: FALSE | K35: FALSE | M35: FALSE | O35: TRUE | Q35: TRUE
A36: =IF(COUNTIF(I36:R36, TRUE) >= 2, "Complete", "In Progress") -> Complete | B36: 37 | C36: T17 | D36: Abstract | E36: Nicholas Benton | F36: Mosquito, Sugar, Survival, Reproduction, Feeding | G36: Seminar Talk | H36: Ecology | I36: FALSE | K36: TRUE | M36: FALSE | O36: FALSE | Q36: TRUE
A37: =IF(COUNTIF(I37:R37, TRUE) >= 2, "Complete", "In Progress") -> Complete | B37: 39 | C37: T2 | D37: Abstract | E37: Matthew, Summerville | F37: Vineyards, Biodiversity, Organic, Native Species, Leafhoppers | G37: Seminar Talk | H37: Ecology | I37: FALSE | K37: TRUE | M37: FALSE | O37: FALSE | Q37: TRUE
A38: =IF(COUNTIF(I38:R38, TRUE) >= 2, "Complete", "In Progress") -> In Progress | B38: 40 | C38: T5 | D38: Abstract | E38: Sophia D'Aurora | F38: lake whitefish, acoustic telemetry, Laurentian Great Lakes, GLATOS, home ranges | G38: Seminar Talk | H38: Ecology | I38: TRUE | J38: Sophie repsonded and is now on the abstract | K38: FALSE | L38: Sophia is not listed as an author on the abstract... | M38: FALSE | O38: FALSE | Q38: FALSE | R38: I agree with Kat, Sophia isn't on the author list
A39: =IF(COUNTIF(I39:R39, TRUE) >= 2, "Complete", "In Progress") -> Complete | B39: 16 | C39: T13 | D39: Abstract | E39: Melanie, Denommé | F39: Reptile, Behaviour, Repetitive behaviours, Animal welfare, Husbandry | G39: Seminar Talk | H39: Ethology | I39: FALSE | K39: FALSE | M39: FALSE | O39: TRUE | Q39: TRUE
A40: =IF(COUNTIF(I40:R40, TRUE) >= 2, "Complete", "In Progress") -> Complete | B40: 22 | C40: T16 | D40: Abstract | E40: Lyllian Corbin | F40: male aggression, juvenile hormone, methoprene, territoriality | G40: Seminar Talk | H40: Ethology | I40: TRUE | K40: FALSE | M40: FALSE | O40: TRUE | P40: Merged paragraphs | Q40: TRUE | R40: Merge to one paragraph
A41: =IF(COUNTIF(I41:R41, TRUE) >= 2, "Complete", "In Progress") -> Complete | B41: 26 | C41: T12 | D41: Abstract | E41: Alex Wilder | F41: animal behaviour, communication, zoos | G41: Seminar Talk | H41: Ethology | I41: TRUE | K41: FALSE | M41: FALSE | O41: TRUE | Q41: FALSE
...

Sheet Official Talk Order
B2: Posters
B3: P1 | C3: Abstract | D3: Lauren Nesbitt
B4: P2 | C4: Abstract | D4: Joonsoo Sean Lyeo
B5: P3 | C5: Abstract | D5: Linh Nguyen
B6: P4 | C6: Abstract | D6: Harmandeep Singh
B7: P5 | C7: Abstract | D7: Samia, Saif
B8: P6 | C8: Abstract | D8: Gabriela Santos de Paula
B9: P7 | C9: Abstract | D9: Adrija Paul
B10: P8 | C10: Abstract | D10: Noah Rhoden
B11: P9 | C11: Abstract | D11: Amanda, Liu
B12: P10 | C12: Abstract | D12: Johanna Kiik
B13: P11 | C13: Abstract | D13: Ella Martin
B14: P12 | D14: Sophie Gauthier
B15: P13 | C15: Abstract | D15: Kaley Vance
B16: P14 | C16: Abstract | D16: Morgan Mumma
B17: P15 | C17: Abstract | D17: Avery Ng
B18: P16 | C18: Abstract | D18: Harry, Kumbhani
B19: P17 | C19: Abstract | D19: Paige, Au
B20: P18 | C20: Abstract | D20: Bethany Duford
B21: P19 | C21: Abstract | D21: Anmol Thind
B22: Seminar Talks
B23: T1 | C23: Abstract | D23: Kayla MacNaughton
B24: T2 | C24: Abstract | D24: Matthew, Summerville
B25: T3 | C25: Abstract | D25: Emily Heagney
B26: T4 | C26: Abstract | D26: Sarah Hein
B27: T5 | C27: Abstract | D27: Sophia D'Aurora
B28: T6 | C28: Abstract | D28: Savannah, Ecclestone
B29: T7 | C29: Abstract | D29: Jennika Mitchell
B30: T8 | C30: Abstract | D30: Keshia Lawrence*
B31: T9 | C31: Abstract | D31: Sarah Dunn
B32: T10 | C32: Abstract | D32: Dithara Perera
B33: T11 | C33: Abstract | D33: Joe, Armstrong
B34: T12 | C34: Abstract | D34: Alex Wilder
... B40: T18 | C40: Abstract | D40: Owen Jamieson
B41: Lightning Talks
B42: LT1 | C42: Abstract | D42: Julia Atteck
B43: LT2 | C43: Abstract | D43: Anthony, Loschiavo
B44: LT3 | C44: Abstract | D44: Alexia Kallmes*
B45: LT4 | C45: Abstract | D45: Namanpreet Lamba
B46: LT5 | C46: Abstract | D46: Elora Nabon

Sheet Stats Page
A2: Stats Breakdown | C2: Presentation Type | D2: Number of presentations | E2: % | G2: Representation breakdown | H2: Seminar talk | I2: Lightning Talk | J2: Poster | K2: Total
C3: Seminar Talk | D3: =COUNTIF('Abstract Approval Checklist'!G1:G100,"Seminar Talk") -> 18 | E3: =D3/D6 -> 0.42857143 | G3: Ecology | H3: =COUNTIFS('Abstract Approval Checklist'!G1:G100,"Seminar Talk", 'Abstract Approval Checklist'!H1:H100, "Ecology") -> 11 | I3: =COUNTIFS('Abstract Approval Checklist'!G1:G100,"Lightning Talk", 'Abstract Approval Checklist'!H1:H100, "Ecology") -> 4 | J3: =COUNTIFS('Abstract Approval Checklist'!G1:G100,"Poster", 'Abstract Approval Checklist'!H1:H100, "Ecology") -> 13 | K3: =SUM(H3:J3) -> 28
C4: Lightning Talk | D4: =COUNTIF('Abstract Approval Checklist'!G2:G101,"Lightning Talk") -> 5 | E4: =D4/D6 -> 0.11904762 | G4: Ethology | H4: =COUNTIFS('Abstract Approval Checklist'!G2:G101,"Seminar Talk", 'Abstract Approval Checklist'!H2:H101, "Ethology") -> 5 | I4: =COUNTIFS('Abstract Approval Checklist'!G2:G101,"Lightning Talk", 'Abstract Approval Checklist'!H2:H101, "Ethology") -> 0 | J4: =COUNTIFS('Abstract Approval Checklist'!G2:G101,"Poster", 'Abstract Approval Checklist'!H2:H101, "Ethology") -> 1 | K4: =SUM(H4:J4) -> 6
C5: Poster | D5: =COUNTIF('Abstract Approval Checklist'!G3:G102,"Poster") -> 19 | E5: =D5/D6 -> 0.45238095 | G5: Evolution | H5: =COUNTIFS('Abstract Approval Checklist'!G3:G102,"Seminar Talk", 'Abstract Approval Checklist'!H3:H102, "Evolution") -> 2 | I5: =COUNTIFS('Abstract Approval Checklist'!G3:G102,"Lightning Talk", 'Abstract Approval Checklist'!H3:H102, "Evolution") -> 1 | J5: =COUNTIFS('Abstract Approval Checklist'!G3:G102,"Poster", 'Abstract Approval Checklist'!H3:H102, "Evolution") -> 5 | K5: =SUM(H5:J5) -> 8
C6: Total | D6: =SUM(D3:D5) -> 42 | G6: Total | H6: =SUM(H3:H5) -> 18 | I6: =SUM(I3:I5) -> 5 | J6: =SUM(J3:J5) -> 19 | K6: x
C10: "E" Allignment | D10: Number of presentations | E10: %
C11: Ecology | D11: =COUNTIF('Abstract Approval Checklist'!G1:H108,"Ecology") -> 28 | E11: =D11/D14 -> 0.66666667
C12: Ethology | D12: =COUNTIF('Abstract Approval Checklist'!G2:H109,"Ethology") -> 6 | E12: =D12/D14 -> 0.14285714
C13: Evolution | D13: =COUNTIF('Abstract Approval Checklist'!G3:H110,"Evolution") -> 8 | E13: =D13/D14 -> 0.19047619
C14: Total | D14: =SUM(D11:D13) -> 42

Sheet Concurrent Session 1 (Talks)
A1: Date: | B1: May 1st
A2: Time: | B2: 9:30 to 10:30
A3: Duration: | B3: 1 hour
A4: Theme: | B4: TBD
A5: Abstract Number | B5: Duration | C5: Title of Presentation
A7: 5 min Q and A
A9: 5 min Q and A
A11: 5 min Q and A
A13: 5 min Q and A
A15: SUGGESTION: There are only 5 ethology seminar talks - can they be all in one talk?

Sheet Concurrent Session 2 (Talks)
A1: Date: | B1: May 1st
A2: Time: | B2: 10:45 to 12:00
A3: Duration: | B3: 1 hour 15 minutes
A4: Theme: | B4: TBD
A5: Abstract Number | B5: Duration | C5: Title of Presentation
A7: 5 min Q and A
A9: 5 min Q and A
A11: 5 min Q and A
A13: 5 min Q and A

Sheet Poster Session 1
A1: Date: | B1: May 1st
A2: Time: | B2: 15:00 to 16:00
A3: Duration: | B3: 1 hour
A4: Theme: | B4: TBD
A5: Abstract Number | B5: Duration | C5: Title of Presentation

Sheet Concurrent Session 3 (Talks)
A1: Date: | B1: May 1st
A2: Time: | B2: 16:00 to 17:30
A3: Duration: | B3: 1 hour 30 minutes
A4: Theme: | B4: TBD
A5: Abstract Number | B5: Duration | C5: Title of Presentation
A7: 5 min Q and A
A9: 5 min Q and A
A11: 5 min Q and A
A13: 5 min Q and A

Sheet Concurrent Session 4 (Talks)
A1: Date: | B1: May 2nd
A2: Time: | B2: 9:00 to 10:30
A3: Duration: | B3: 1 hour 30 minutes
A4: Theme: | B4: TBD
A5: Abstract Number | B5: Duration | C5: Title of Presentation
A7: 5 min Q and A
A9: 5 min Q and A
A11: 5 min Q and A
A13: 5 min Q and A

Sheet Concurrent Session 5 (Talks)
A1: Date: | B1: May 2nd
A2: Time: | B2: 10:45 to 12:00
A3: Duration: | B3: 1 hour 30 minutes
A4: Theme: | B4: TBD
A5: Abstract Number | B5: Duration | C5: Title of Presentation
A7: 5 min Q and A
A9: 5 min Q and A
A11: 5 min Q and A
A13: 5 min Q and A

Sheet Poster Session 2
A1: Date: | B1: May 2nd
A2: Time: | B2: 13:00 to 14:00
A3: Duration: | B3: 1 hour
A4: Theme: | B4: TBD
A5: Abstract Number | B5: Duration | C5: Title of Presentation
